Workbook

Sheet Cash Flow Analysis
A1: Year | B1: Net Annual Energy Generation (kWh) | C1: Agricultural Income (INR/annum) | D1: Revenue (INR/annum) | E1: O&M Cost (INR/annum) | F1: Depreciation (INR) | G1: WC Interest (INR) | H1: EMI (INR) | I1: Net Cash Flow (INR) | J1: Discounted Cash Flow (INR) | K1: Cumulative Cash Flow (INR) | L1: Cumulative Discounted CF (INR) | N1: Net Present Value (INR) for 25 years | O1: Total Profitability (INR/acre/year) | P1: Payback Period (Years) | Q1: IRR (in %) for 25 Years
A2: 0 | I2: =-('Inputs and Assumptions'!C8) -> -6000000 | J2: =I2/(1+11.46%)^A2 -> -6000000 | K2: =I2 -> -6000000 | L2: =J2 -> -6000000 | N2: =SUM(I2:I27)/25 -> 1344587.8 | O2: =N2/2.96 -> 454252.63 | P2: =A7-(K7/I8) -> 5.2847261 | Q2: =IRR(I2:I27) -> 0.19194817
A3: 1 | B3: ='Inputs and Assumptions'!C48 -> 938984.4 | C3: ='Inputs and Assumptions'!$C$52 -> 296000 | D3: =B3*3.14+C3 -> 3244411 | E3: ='Inputs and Assumptions'!C38 -> 150000 | F3: ='Inputs and Assumptions'!$C$21 -> 934000 | G3: =IF(A3<=15,'Inputs and Assumptions'!$C$36,0) -> 71700 | H3: =IF(A3<=15,'Inputs and Assumptions'!$C$17,0) -> 1825947.6 | I3: =(D3-(E3+G3+H3)) -> 1196763.5 | J3: =I3/(1+11.46%)^A3 -> 1073715.6 | K3: =K2+I3 -> -4803236.5 | L3: =L2+J3 -> -4926284.4
A4: 2 | B4: =B3*(1-0.007)^(A4-A3) -> 932411.51 | C4: ='Inputs and Assumptions'!$C$52 -> 296000 | D4: =B4*3.14+C4 -> 3223772.1 | E4: =E3*(1+0.05) -> 157500 | F4: ='Inputs and Assumptions'!$C$21 -> 934000 | G4: =IF(A4<=15,'Inputs and Assumptions'!$C$36,0) -> 71700 | H4: =IF(A4<=15,'Inputs and Assumptions'!$C$17,0) -> 1825947.6 | I4: =(D4-(E4+G4+H4)) -> 1168624.6 | J4: =I4/(1+11.46%)^A4 -> 940669.24 | K4: =K3+I4 -> -3634612 | L4: =L3+J4 -> -3985615.1
A5: 3 | B5: =B4*(1-0.007)^(A5-A4) -> 925884.63 | C5: ='Inputs and Assumptions'!$C$52 -> 296000 | D5: =B5*3.14+C5 -> 3203277.7 | E5: =E4*(1+0.05) -> 165375 | F5: ='Inputs and Assumptions'!$C$21 -> 934000 | G5: =IF(A5<=15,'Inputs and Assumptions'!$C$36,0) -> 71700 | H5: =IF(A5<=15,'Inputs and Assumptions'!$C$17,0) -> 1825947.6 | I5: =(D5-(E5+G5+H5)) -> 1140255.2 | J5: =I5/(1+11.46%)^A5 -> 823464.61 | K5: =K4+I5 -> -2494356.8 | L5: =L4+J5 -> -3162150.5
A6: 4 | B6: =B5*(1-0.007)^(A6-A5) -> 919403.44 | C6: ='Inputs and Assumptions'!$C$52 -> 296000 | D6: =B6*3.14+C6 -> 3182926.8 | E6: =E5*(1+0.05) -> 173643.75 | F6: ='Inputs and Assumptions'!$C$21 -> 934000 | G6: =IF(A6<=15,'Inputs and Assumptions'!$C$36,0) -> 71700 | H6: =IF(A6<=15,'Inputs and Assumptions'!$C$17,0) -> 1825947.6 | I6: =(D6-(E6+G6+H6)) -> 1111635.5 | J6: =I6/(1+11.46%)^A6 -> 720254.94 | K6: =K5+I6 -> -1382721.3 | L6: =L5+J6 -> -2441895.6
A7: 5 | B7: =B6*(1-0.007)^(A7-A6) -> 912967.61 | C7: ='Inputs and Assumptions'!$C$52 -> 296000 | D7: =B7*3.14+C7 -> 3162718.3 | E7: =E6*(1+0.05) -> 182325.94 | F7: ='Inputs and Assumptions'!$C$21 -> 934000 | G7: =IF(A7<=15,'Inputs and Assumptions'!$C$36,0) -> 71700 | H7: =IF(A7<=15,'Inputs and Assumptions'!$C$17,0) -> 1825947.6 | I7: =(D7-(E7+G7+H7)) -> 1082744.8 | J7: =I7/(1+11.46%)^A7 -> 629406.06 | K7: =K6+I7 -> -299976.48 | L7: =L6+J7 -> -1812489.5
A8: 6 | B8: =B7*(1-0.007)^(A8-A7) -> 906576.84 | C8: ='Inputs and Assumptions'!$C$52 -> 296000 | D8: =B8*3.14+C8 -> 3142651.3 | E8: =E7*(1+0.05) -> 191442.23 | F8: ='Inputs and Assumptions'!$C$21 -> 934000 | G8: =IF(A8<=15,'Inputs and Assumptions'!$C$36,0) -> 71700 | H8: =IF(A8<=15,'Inputs and Assumptions'!$C$17,0) -> 1825947.6 | I8: =(D8-(E8+G8+H8)) -> 1053561.5 | J8: =I8/(1+11.46%)^A8 -> 549472.11 | K8: =K7+I8 -> 753585 | L8: =L7+J8 -> -1263017.4
A9: 7 | B9: =B8*(1-0.007)^(A9-A8) -> 900230.8 | C9: ='Inputs and Assumptions'!$C$52 -> 296000 | D9: =B9*3.14+C9 -> 3122724.7 | E9: =E8*(1+0.05) -> 201014.35 | F9: ='Inputs and Assumptions'!$C$21 -> 934000 | G9: =IF(A9<=15,'Inputs and Assumptions'!$C$36,0) -> 71700 | H9: =IF(A9<=15,'Inputs and Assumptions'!$C$17,0) -> 1825947.6 | I9: =(D9-(E9+G9+H9)) -> 1024062.8 | J9: =I9/(1+11.46%)^A9 -> 479174.09 | K9: =K8+I9 -> 1777647.8 | L9: =L8+J9 -> -783843.32
A10: 8 | B10: =B9*(1-0.007)^(A10-A9) -> 893929.19 | C10: ='Inputs and Assumptions'!$C$52 -> 296000 | D10: =B10*3.14+C10 -> 3102937.6 | E10: =E9*(1+0.05) -> 211065.06 | F10: ='Inputs and Assumptions'!$C$21 -> 934000 | G10: =IF(A10<=15,'Inputs and Assumptions'!$C$36,0) -> 71700 | H10: =IF(A10<=15,'Inputs and Assumptions'!$C$17,0) -> 1825947.6 | I10: =(D10-(E10+G10+H10)) -> 994225.02 | J10: =I10/(1+11.46%)^A10 -> 417380.72 | K10: =K9+I10 -> 2771872.8 | L10: =L9+J10 -> -366462.6
A11: 9 | B11: =B10*(1-0.007)^(A11-A10) -> 887671.68 | C11: ='Inputs and Assumptions'!$C$52 -> 296000 | D11: =B11*3.14+C11 -> 3083289.1 | E11: =E10*(1+0.05) -> 221618.32 | F11: ='Inputs and Assumptions'!$C$21 -> 934000 | G11: =IF(A11<=15,'Inputs and Assumptions'!$C$36,0) -> 71700 | H11: =IF(A11<=15,'Inputs and Assumptions'!$C$17,0) -> 1825947.6 | I11: =(D11-(E11+G11+H11)) -> 964023.21 | J11: =I11/(1+11.46%)^A11 -> 363091.55 | K11: =K10+I11 -> 3735896 | L11: =L10+J11 -> -3371.0503
A12: 10 | B12: =B11*(1-0.007)^(A12-A11) -> 881457.98 | C12: ='Inputs and Assumptions'!$C$52 -> 296000 | D12: =B12*3.14+C12 -> 3063778.1 | E12: =E11*(1+0.05) -> 232699.23 | F12: ='Inputs and Assumptions'!$C$21 -> 934000 | G12: =IF(A12<=15,'Inputs and Assumptions'!$C$36,0) -> 71700 | H12: =IF(A12<=15,'Inputs and Assumptions'!$C$17,0) -> 1825947.6 | I12: =(D12-(E12+G12+H12)) -> 933431.27 | J12: =I12/(1+11.46%)^A12 -> 315421.98 | K12: =K11+I12 -> 4669327.3 | L12: =L11+J12 -> 312050.93
A13: 11 | B13: =B12*(1-0.007)^(A13-A12) -> 875287.77 | C13: ='Inputs and Assumptions'!$C$52 -> 296000 | D13: =B13*3.14+C13 -> 3044403.6 | E13: =E12*(1+0.05) -> 244334.19 | F13: ='Inputs and Assumptions'!$C$21 -> 934000 | G13: =IF(A13<=15,'Inputs and Assumptions'!$C$36,0) -> 71700 | H13: =IF(A13<=15,'Inputs and Assumptions'!$C$17,0) -> 1825947.6 | I13: =(D13-(E13+G13+H13)) -> 902421.86 | J13: =I13/(1+11.46%)^A13 -> 273589.98 | K13: =K12+I13 -> 5571749.2 | L13: =L12+J13 -> 585640.91
A14: 12 | B14: =B13*(1-0.007)^(A14-A13) -> 869160.76 | C14: ='Inputs and Assumptions'!$C$52 -> 296000 | D14: =B14*3.14+C14 -> 3025164.8 | E14: =E13*(1+0.05) -> 256550.9 | F14: ='Inputs and Assumptions'!$C$21 -> 934000 | G14: =IF(A14<=15,'Inputs and Assumptions'!$C$36,0) -> 71700 | H14: =IF(A14<=15,'Inputs and Assumptions'!$C$17,0) -> 1825947.6 | I14: =(D14-(E14+G14+H14)) -> 870966.32 | J14: =I14/(1+11.46%)^A14 -> 236904.28 | K14: =K13+I14 -> 6442715.5 | L14: =L13+J14 -> 822545.18
A15: 13 | B15: =B14*(1-0.007)^(A15-A14) -> 863076.63 | C15: ='Inputs and Assumptions'!$C$52 -> 296000 | D15: =B15*3.14+C15 -> 3006060.6 | E15: =E14*(1+0.05) -> 269378.45 | F15: ='Inputs and Assumptions'!$C$21 -> 934000 | G15: =IF(A15<=15,'Inputs and Assumptions'!$C$36,0) -> 71700 | H15: =IF(A15<=15,'Inputs and Assumptions'!$C$17,0) -> 1825947.6 | I15: =(D15-(E15+G15+H15)) -> 839034.63 | J15: =I15/(1+11.46%)^A15 -> 204753.99 | K15: =K14+I15 -> 7281750.1 | L15: =L14+J15 -> 1027299.2
... A17: 15 | B17: =B16*(1-0.007)^(A17-A16) -> 851035.85 | C17: ='Inputs and Assumptions'!$C$52 -> 296000 | D17: =B17*3.14+C17 -> 2968252.6 | E17: =E16*(1+0.05) -> 296989.74 | F17: ='Inputs and Assumptions'!$C$21 -> 934000 | G17: =IF(A17<=15,'Inputs and Assumptions'!$C$36,0) -> 71700 | H17: =IF(A17<=15,'Inputs and Assumptions'!$C$17,0) -> 1825947.6 | I17: =(D17-(E17+G17+H17)) -> 773615.28 | J17: =I17/(1+11.46%)^A17 -> 151963.56 | K17: =K16+I17 -> 8861960.7 | L17: =L16+J17 -> 1355862.1
A18: 16 | B18: =B17*(1-0.007)^(A18-A17) -> 845078.6 | C18: ='Inputs and Assumptions'!$C$52 -> 296000 | D18: =B18*3.14+C18 -> 2949546.8 | E18: =E17*(1+0.05) -> 311839.23 | F18: ='Inputs and Assumptions'!$C$23 -> 400000 | G18: =IF(A18<=15,'Inputs and Assumptions'!$C$36,0) -> 0 | H18: =IF(A18<=15,'Inputs and Assumptions'!$C$17,0) -> 0 | I18: =(D18-(E18+G18+H18)) -> 2637707.6 | J18: =I18/(1+11.46%)^A18 -> 464859.84 | K18: =K17+I18 -> 11499668 | L18: =L17+J18 -> 1820721.9
A19: 17 | B19: =B18*(1-0.007)^(A19-A18) -> 839163.05 | C19: ='Inputs and Assumptions'!$C$52 -> 296000 | D19: =B19*3.14+C19 -> 2930972 | E19: =E18*(1+0.05) -> 327431.19 | F19: ='Inputs and Assumptions'!$C$23 -> 400000 | G19: =IF(A19<=15,'Inputs and Assumptions'!$C$36,0) -> 0 | H19: =IF(A19<=15,'Inputs and Assumptions'!$C$17,0) -> 0 | I19: =(D19-(E19+G19+H19)) -> 2603540.8 | J19: =I19/(1+11.46%)^A19 -> 411661.95 | K19: =K18+I19 -> 14103209 | L19: =L18+J19 -> 2232383.9
A20: 18 | B20: =B19*(1-0.007)^(A20-A19) -> 833288.91 | C20: ='Inputs and Assumptions'!$C$52 -> 296000 | D20: =B20*3.14+C20 -> 2912527.2 | E20: =E19*(1+0.05) -> 343802.75 | F20: ='Inputs and Assumptions'!$C$23 -> 400000 | G20: =IF(A20<=15,'Inputs and Assumptions'!$C$36,0) -> 0 | H20: =IF(A20<=15,'Inputs and Assumptions'!$C$17,0) -> 0 | I20: =(D20-(E20+G20+H20)) -> 2568724.4 | J20: =I20/(1+11.46%)^A20 -> 364397.02 | K20: =K19+I20 -> 16671933 | L20: =L19+J20 -> 2596780.9
A21: 19 | B21: =B20*(1-0.007)^(A21-A20) -> 827455.89 | C21: ='Inputs and Assumptions'!$C$52 -> 296000 | D21: =B21*3.14+C21 -> 2894211.5 | E21: =E20*(1+0.05) -> 360992.89 | F21: ='Inputs and Assumptions'!$C$23 -> 400000 | G21: =IF(A21<=15,'Inputs and Assumptions'!$C$36,0) -> 0 | H21: =IF(A21<=15,'Inputs and Assumptions'!$C$17,0) -> 0 | I21: =(D21-(E21+G21+H21)) -> 2533218.6 | J21: =I21/(1+11.46%)^A21 -> 322411.8 | K21: =K20+I21 -> 19205152 | L21: =L20+J21 -> 2919192.7
A22: 20 | B22: =B21*(1-0.007)^(A22-A21) -> 821663.7 | C22: ='Inputs and Assumptions'!$C$52 -> 296000 | D22: =B22*3.14+C22 -> 2876024 | E22: =E21*(1+0.05) -> 379042.53 | F22: ='Inputs and Assumptions'!$C$23 -> 400000 | G22: =IF(A22<=15,'Inputs and Assumptions'!$C$36,0) -> 0 | H22: =IF(A22<=15,'Inputs and Assumptions'!$C$17,0) -> 0 | I22: =(D22-(E22+G22+H22)) -> 2496981.5 | J22: =I22/(1+11.46%)^A22 -> 285124.51 | K22: =K21+I22 -> 21702134 | L22: =L21+J22 -> 3204317.2
A23: 21 | B23: =B22*(1-0.007)^(A23-A22) -> 815912.05 | C23: ='Inputs and Assumptions'!$C$52 -> 296000 | D23: =B23*3.14+C23 -> 2857963.8 | E23: =E22*(1+0.05) -> 397994.66 | F23: ='Inputs and Assumptions'!$C$23 -> 400000 | G23: =IF(A23<=15,'Inputs and Assumptions'!$C$36,0) -> 0 | H23: =IF(A23<=15,'Inputs and Assumptions'!$C$17,0) -> 0 | I23: =(D23-(E23+G23+H23)) -> 2459969.2 | J23: =I23/(1+11.46%)^A23 -> 252017.01 | K23: =K22+I23 -> 24162103 | L23: =L22+J23 -> 3456334.2
A24: 22 | B24: =B23*(1-0.007)^(A24-A23) -> 810200.67 | C24: ='Inputs and Assumptions'!$C$52 -> 296000 | D24: =B24*3.14+C24 -> 2840030.1 | E24: =E23*(1+0.05) -> 417894.39 | F24: ='Inputs and Assumptions'!$C$23 -> 400000 | G24: =IF(A24<=15,'Inputs and Assumptions'!$C$36,0) -> 0 | H24: =IF(A24<=15,'Inputs and Assumptions'!$C$17,0) -> 0 | I24: =(D24-(E24+G24+H24)) -> 2422135.7 | J24: =I24/(1+11.46%)^A24 -> 222627.92 | K24: =K23+I24 -> 26584238 | L24: =L23+J24 -> 3678962.1
A25: 23 | B25: =B24*(1-0.007)^(A25-A24) -> 804529.26 | C25: ='Inputs and Assumptions'!$C$52 -> 296000 | D25: =B25*3.14+C25 -> 2822221.9 | E25: =E24*(1+0.05) -> 438789.11 | F25: ='Inputs and Assumptions'!$C$23 -> 400000 | G25: =IF(A25<=15,'Inputs and Assumptions'!$C$36,0) -> 0 | H25: =IF(A25<=15,'Inputs and Assumptions'!$C$17,0) -> 0 | I25: =(D25-(E25+G25+H25)) -> 2383432.8 | J25: =I25/(1+11.46%)^A25 -> 196546.36 | K25: =K24+I25 -> 28967671 | L25: =L24+J25 -> 3875508.5
A26: 24 | B26: =B25*(1-0.007)^(A26-A25) -> 798897.56 | C26: ='Inputs and Assumptions'!$C$52 -> 296000 | D26: =B26*3.14+C26 -> 2804538.3 | E26: =E25*(1+0.05) -> 460728.56 | F26: ='Inputs and Assumptions'!$C$23 -> 400000 | G26: =IF(A26<=15,'Inputs and Assumptions'!$C$36,0) -> 0 | H26: =IF(A26<=15,'Inputs and Assumptions'!$C$17,0) -> 0 | I26: =(D26-(E26+G26+H26)) -> 2343809.8 | J26: =I26/(1+11.46%)^A26 -> 173406.52 | K26: =K25+I26 -> 31311481 | L26: =L25+J26 -> 4048915
A27: 25 | B27: =B26*(1-0.007)^(A27-A26) -> 793305.27 | C27: ='Inputs and Assumptions'!$C$52 -> 296000 | D27: =B27*3.14+C27 -> 2786978.6 | E27: =E26*(1+0.05) -> 483764.99 | F27: ='Inputs and Assumptions'!$C$23 -> 400000 | G27: =IF(A27<=15,'Inputs and Assumptions'!$C$36,0) -> 0 | H27: =IF(A27<=15,'Inputs and Assumptions'!$C$17,0) -> 0 | I27: =(D27-(E27+G27+H27)) -> 2303213.6 | J27: =I27/(1+11.46%)^A27 -> 152882.66 | K27: =K26+I27 -> 33614695 | L27: =L26+J27 -> 4201797.7

Sheet Inputs and Assumptions
A1: Project Finance | B1: Variable | C1: Value
B2: Project Size (MW) | C2: 0.6
B3: Useful Life (Years) | C3: 25
B4: Total Capital Cost (INR) | C4: =20000000 -> 20000000
B5: Debt Ratio | C5: 0.7
B6: Equity Ratio | C6: 0.3
B7: Debt Amount (INR) | C7: =C4*C5 -> 14000000
B8: Equity Amount (INR) | C8: =C4*C6 -> 6000000
B9: Return on Equity (ROE) (%) | C9: 0.1647
B10: Return on Equity (ROE) (INR) | C10: =C9*C8 -> 988200
B11: Discount Rate (%) | C11: 0.1146
A13: Loan Terms | B13: Loan Tenure (Years) | C13: 15
B14: Interest Rate (%) | C14: 0.1025
B15: Monthly Interest Rate(%) | C15: =C14/12 -> 0.0085416667
B16: Monthly EMI (INR) | C16: =PMT(0.0085,180,-(C7)) -> 152162.3
B17: Annual EMI (INR) | C17: =ABS(C16*12) -> 1825947.6
A19: Depreciation | B19: Depreciation Rate (Years 1-15) (%) | C19: 0.0467
B20: Salvage Value (%) | C20: 0.1
B21: Depriciation(1st 15 years)(INR) | C21: =C4*C19 -> 934000
B22: Depreciation Rate (Years 16-25) (%) | C22: 0.02
B23: Depriciation(16th Year to 25th Year) (INR) | C23: =C4*C22 -> 400000
B24: Debt % Of Depreciation(INR) (1-15 Years) | C24: =C5*C21 -> 653800
B25: Debt % Of Depreciation(INR) (16-25 Years) | C25: =C5*C23 -> 280000
B26: Salvage Value (INR) | C26: =C20*C4 -> 2000000
B27: Total Depriciable (INR) | C27: =C4-C26 -> 18000000
B28: Total Depriciable(1st 15 years) (INR) | C28: =C21*C13 -> 14010000
B29: Total Depriciable(Last 10 years) (INR) | C29: =C27-C28 -> 3990000
B30: Depriciation(Last 10 years) (INR) | C30: =C29/10 -> 399000
B31: Debt % Of Depreciation(INR) (16-25 Years) | C31: =C5*C30 -> 279300
A33: Working Capital | B33: Working Capital (% of Capital Cost) | C33: 0.03
B34: Working Capital (INR) | C34: =C33*C4 -> 600000
B35: Working Capital Interest Rate (%) | C35: 0.1195
B36: Annual Interest on Working Capital (INR) | C36: =C34*C35 -> 71700
A38: Variable Cost | B38: Initial O&M Expense (INR) | C38: 150000
B39: O&M Escalation (%) | C39: 0.05
B40: Total Land (Acre) | C40: 2.96
A42: Generation | B42: Annual Runtime | C42: 8760
B43: CUF (%) | C43: 0.18
B44: Gross Annual Energy Generation (kWh) | C44: =C42*C43*C2*1000 -> 946080
B45: kWh/kWp/year | C45: =C44/600 -> 1576.8
...
